<?xml version="1.0"?>
<robot name="three_link_arm">
  <!-- Link 1 -->
  <link name="link1">
    <inertial>
      <mass value="0.5"/>
      <origin xyz="0 0 -0.25" rpy="0 0 0"/>
      <inertia ixx="0.00083" ixy="0" ixz="0" iyy="0.00083" iyz="0" izz="0.00001"/>
    </inertial>
    <visual>
      <origin xyz="0 0 -0.25" rpy="0 0 0"/>
      <geometry>
        <cylinder length="0.5" radius="0.02"/>
      </geometry>
      <material name="blue">
        <color rgba="0 0 1 1"/>
      </material>
    </visual>
    <collision>
      <origin xyz="0 0 -0.25" rpy="0 0 0"/>
      <geometry>
        <cylinder length="0.5" radius="0.02"/>
      </geometry>
    </collision>
  </link>

  <!-- Link 2 -->
  <link name="link2">
    <inertial>
      <mass value="0.5"/>
      <origin xyz="0 0 -0.25" rpy="0 0 0"/>
      <inertia ixx="0.00083" ixy="0" ixz="0" iyy="0.00083" iyz="0" izz="0.00001"/>
    </inertial>
    <visual>
      <origin xyz="0 0 -0.25" rpy="0 0 0"/>
      <geometry>
        <cylinder length="0.5" radius="0.02"/>
      </geometry>
      <material name="green">
        <color rgba="0 1 0 1"/>
      </material>
    </visual>
    <collision>
      <origin xyz="0 0 -0.25" rpy="0 0 0"/>
      <geometry>
        <cylinder length="0.5" radius="0.02"/>
      </geometry>
    </collision>
  </link>

  <!-- Link 3 -->
  <link name="link3">
    <inertial>
      <mass value="0.25"/>
      <origin xyz="0 0 -0.125" rpy="0 0 0"/>
      <inertia ixx="0.00010" ixy="0" ixz="0" iyy="0.00010" iyz="0" izz="0.000005"/>
    </inertial>
    <visual>
      <origin xyz="0 0 -0.125" rpy="0 0 0"/>
      <geometry>
        <cylinder length="0.25" radius="0.02"/>
      </geometry>
      <material name="red">
        <color rgba="1 0 0 1"/>
      </material>
    </visual>
    <collision>
      <origin xyz="0 0 -0.125" rpy="0 0 0"/>
      <geometry>
        <cylinder length="0.25" radius="0.02"/>
      </geometry>
    </collision>
  </link>

  <!-- Joint 1 -->
  <joint name="joint1" type="revolute">
    <parent link="base_link"/>
    <child link="link1"/>
    <origin xyz="0 0 0" rpy="0 0 0"/>
    <axis xyz="0 1 0"/>
    <limit effort="10" velocity="2" lower="-3.1416" upper="3.1416"/>
  </joint>

  <!-- Joint 2 -->
  <joint name="joint2" type="revolute">
    <parent link="link1"/>
    <child link="link2"/>
    <origin xyz="0 0 -0.5" rpy="0 0 0"/>
    <axis xyz="1 0 0"/>
    <limit effort="10" velocity="2" lower="-3.1416" upper="3.1416"/>
  </joint>

  <!-- Joint 3 -->
  <joint name="joint3" type="revolute">
    <parent link="link2"/>
    <child link="link3"/>
    <origin xyz="0 0 -0.5" rpy="0 0 0"/>
    <axis xyz="1 0 0"/>
    <limit effort="5" velocity="2" lower="-3.1416" upper="3.1416"/>
  </joint>

  <!-- Base Link -->
  <link name="base_link">
    <visual>
      <origin xyz="0 0 0" rpy="0 0 0"/>
      <geometry>
        <box size="0.1 0.1 0.1"/>
      </geometry>
      <material name="grey">
        <color rgba="0.5 0.5 0.5 1"/>
      </material>
    </visual>
    <collision>
      <origin xyz="0 0 0" rpy="0 0 0"/>
      <geometry>
        <box size="0.1 0.1 0.1"/>
      </geometry>
    </collision>
  </link>
</robot>
